<?xml version="1.0" encoding="utf-8"?>
<!-- This URDF was automatically created by SolidWorks to URDF Exporter! Originally created by Stephen Brawner (brawner@gmail.com) 
     Commit Version: 1.5.1-0-g916b5db  Build Version: 1.5.7152.31018
     For more information, please see http://wiki.ros.org/sw_urdf_exporter -->
<robot
  name="robot">
  <link
    name="base_link">
    <inertial>
      <origin
        xyz="-0.00367118917753315 0.000218298627754743 0.14845566994301"
        rpy="0 0 0" />
      <mass
        value="43.7289793607304" />
      <inertia
        ixx="0.42588144392919"
        ixy="-0.000297484646334764"
        ixz="-0.00164840993407266"
        iyy="0.81830308668807"
        iyz="8.85091130367399E-05"
        izz="1.02122466419532" />
    </inertial>
    <visual>
      <origin
        xyz="0 0 0"
        rpy="0 0 0" />
      <geometry>
        <mesh
          filename="package://robot/meshes/base_link.STL" />
      </geometry>
      <material
        name="">
        <color
          rgba="0.650980392156863 0.619607843137255 0.588235294117647 1" />
      </material>
    </visual>
    <collision>
      <origin
        xyz="0 0 0"
        rpy="0 0 0" />
      <geometry>
        <mesh
          filename="package://robot/meshes/base_link.STL" />
      </geometry>
    </collision>
  </link>
  <link
    name="front_right_Link">
    <inertial>
      <origin
        xyz="-8.32667268468867E-17 -2.77555756156289E-17 -0.0434410741094558"
        rpy="0 0 0" />
      <mass
        value="0.58827061564709" />
      <inertia
        ixx="0.00095358669788381"
        ixy="-2.83368080783419E-19"
        ixz="8.05956179241043E-19"
        iyy="0.00095358669788381"
        iyz="3.12289332904768E-19"
        izz="0.00152472894751309" />
    </inertial>
    <visual>
      <origin
        xyz="0 0 0"
        rpy="0 0 0" />
      <geometry>
        <mesh
          filename="package://robot/meshes/front_right_Link.STL" />
      </geometry>
      <material
        name="">
        <color
          rgba="0.752941176470588 0.752941176470588 0.752941176470588 1" />
      </material>
    </visual>
    <collision>
      <origin
        xyz="0 0 0"
        rpy="0 0 0" />
      <geometry>
        <mesh
          filename="package://robot/meshes/front_right_Link.STL" />
      </geometry>
    </collision>


  </link>
  <joint
    name="front_right"
    type="continuous">
    <origin
      xyz="0.155 -0.15 0.069"
      rpy="-1.5708 0 0" />
    <parent
      link="base_link" />
    <child
      link="front_right_Link" />
    <axis
      xyz="0 0 -1" />
  </joint>
  <link
    name="front_left_Link">
    <inertial>
      <origin
        xyz="-5.27355936696949E-16 1.94289029309402E-16 -0.0434410741094559"
        rpy="0 0 0" />
      <mass
        value="0.588270615647091" />
      <inertia
        ixx="0.000953586697883812"
        ixy="-7.74143663737727E-20"
        ixz="-8.3999833581235E-20"
        iyy="0.000953586697883811"
        iyz="-3.11944093140453E-19"
        izz="0.0015247289475131" />
    </inertial>
    <visual>
      <origin
        xyz="0 0 0"
        rpy="0 0 0" />
      <geometry>
        <mesh
          filename="package://robot/meshes/front_left_Link.STL" />
      </geometry>
      <material
        name="">
        <color
          rgba="0.752941176470588 0.752941176470588 0.752941176470588 1" />
      </material>
    </visual>
    <collision>
      <origin
        xyz="0 0 0"
        rpy="0 0 0" />
      <geometry>
        <mesh
          filename="package://robot/meshes/front_left_Link.STL" />
      </geometry>
    </collision>
  </link>
  <joint
    name="front_left"
    type="continuous">
    <origin
      xyz="0.155 0.15 0.069"
      rpy="1.5708 0 0" />
    <parent
      link="base_link" />
    <child
      link="front_left_Link" />
    <axis
      xyz="0 0 -1" />
  </joint>
  <link
    name="back_left_Link">
    <inertial>
      <origin
        xyz="-8.32667268468867E-17 2.77555756156289E-17 -0.0434410741094559"
        rpy="0 0 0" />
      <mass
        value="0.58827061564709" />
      <inertia
        ixx="0.00095358669788381"
        ixy="-1.50202746509935E-19"
        ixz="-5.89492059668342E-19"
        iyy="0.00095358669788381"
        iyz="-3.64288864773973E-19"
        izz="0.00152472894751309" />
    </inertial>
    <visual>
      <origin
        xyz="0 0 0"
        rpy="0 0 0" />
      <geometry>
        <mesh
          filename="package://robot/meshes/back_left_Link.STL" />
      </geometry>
      <material
        name="">
        <color
          rgba="0.752941176470588 0.752941176470588 0.752941176470588 1" />
      </material>
    </visual>
    <collision>
      <origin
        xyz="0 0 0"
        rpy="0 0 0" />
      <geometry>
        <mesh
          filename="package://robot/meshes/back_left_Link.STL" />
      </geometry>
    </collision>
  </link>
  <joint
    name="back_left"
    type="continuous">
    <origin
      xyz="-0.135 0.15 0.069"
      rpy="1.5708 0 0" />
    <parent
      link="base_link" />
    <child
      link="back_left_Link" />
    <axis
      xyz="0 0 1" />
  </joint>
  <link
    name="back_right_Link">
    <inertial>
      <origin
        xyz="5.55111512312578E-17 -1.11022302462516E-16 -0.0434410741094558"
        rpy="0 0 0" />
      <mass
        value="0.588270615647089" />
      <inertia
        ixx="0.00095358669788381"
        ixy="-3.05792283667184E-19"
        ixz="7.85359670835562E-20"
        iyy="0.000953586697883809"
        iyz="5.60320527161336E-19"
        izz="0.00152472894751309" />
    </inertial>
    <visual>
      <origin
        xyz="0 0 0"
        rpy="0 0 0" />
      <geometry>
        <mesh
          filename="package://robot/meshes/back_right_Link.STL" />
      </geometry>
      <material
        name="">
        <color
          rgba="0.752941176470588 0.752941176470588 0.752941176470588 1" />
      </material>
    </visual>
    <collision>
      <origin
        xyz="0 0 0"
        rpy="0 0 0" />
      <geometry>
        <mesh
          filename="package://robot/meshes/back_right_Link.STL" />
      </geometry>
    </collision>
  </link>
  <joint
    name="back_right"
    type="continuous">
    <origin
      xyz="-0.135 -0.15 0.069"
      rpy="-1.5708 0 0" />
    <parent
      link="base_link" />
    <child
      link="back_right_Link" />
    <axis
      xyz="0 0 1" />
  </joint>
  <link
    name="laser_Link">
    <inertial>
      <origin
        xyz="-0.000191890889836788 -8.07619959797279E-09 0.00798455062925515"
        rpy="0 0 0" />
      <mass
        value="0.0296109461913993" />
      <inertia
        ixx="2.22315185792305E-06"
        ixy="6.16384968776179E-13"
        ixz="3.01173164023526E-08"
        iyy="2.22350354866726E-06"
        iyz="1.29880393109063E-12"
        izz="3.08750342269333E-06" />
    </inertial>
    <visual>
      <origin
        xyz="0 0 0"
        rpy="0 0 0" />
      <geometry>
        <mesh
          filename="package://robot/meshes/laser_Link.STL" />
      </geometry>
      <material
        name="">
        <color
          rgba="0.898039215686275 0.917647058823529 0.929411764705882 1" />
      </material>
    </visual>
    <collision>
      <origin
        xyz="0 0 0"
        rpy="0 0 0" />
      <geometry>
        <mesh
          filename="package://robot/meshes/laser_Link.STL" />
      </geometry>
    </collision>
  </link>
  <joint
    name="laser"
    type="fixed">
    <origin
      xyz="0.205 0 0.156"
      rpy="0 0 0" />
    <parent
      link="base_link" />
    <child
      link="laser_Link" />
    <axis
      xyz="0 0 0" />
  </joint>
  <link
    name="kinect_Link">
    <inertial>
      <origin
        xyz="-9.21591052125137E-05 5.0468776315038E-05 0.0386925485164369"
        rpy="0 0 0" />
      <mass
        value="1.88003749355829" />
      <inertia
        ixx="0.00561268771998165"
        ixy="-2.27771633536026E-06"
        ixz="1.09284530959139E-06"
        iyy="0.000757085904553865"
        iyz="-5.98470784784347E-07"
        izz="0.00556343302687423" />
    </inertial>
    <visual>
      <origin
        xyz="0 0 0"
        rpy="0 0 0" />
      <geometry>
        <mesh
          filename="package://robot/meshes/kinect_Link.STL" />
      </geometry>
      <material
        name="">
        <color
          rgba="0.776470588235294 0.756862745098039 0.737254901960784 1" />
      </material>
    </visual>
    <collision>
      <origin
        xyz="0 0 0"
        rpy="0 0 0" />
      <geometry>
        <mesh
          filename="package://robot/meshes/kinect_Link.STL" />
      </geometry>
    </collision>
  </link>
  <joint
    name="kinect"
    type="fixed">
    <origin
      xyz="0.185 0 0.207"
      rpy="0 0 0" />
    <parent
      link="base_link" />
    <child
      link="kinect_Link" />
    <axis
      xyz="0 0 0" />
  </joint>

    <gazebo>
    <plugin name="differential_drive_controller" filename="libgazebo_ros_diff_drive.so">
      <legacyMode>false</legacyMode>
      <alwaysOn>true</alwaysOn>
      <updateRate>10</updateRate>
      <leftJoint>back_left</leftJoint>
      <rightJoint>back_right</rightJoint>
      <wheelSeparation>0.4</wheelSeparation>
      <wheelDiameter>0.3</wheelDiameter>
      <torque>10</torque>
      <commandTopic>cmd_vel</commandTopic>
      <odometryTopic>odom</odometryTopic>
      <odometryFrame>odom</odometryFrame>

      <robotBaseFrame>base_link</robotBaseFrame>
      <odometrySource>base_link</odometrySource>
    <publishWheelTF>true</publishWheelTF>
    <publishOdom>true</publishOdom>
    <publishOdomTF>true</publishOdomTF>
    <publishWheelJointState>true</publishWheelJointState>
    <rosDebugLevel>na</rosDebugLevel>
    <wheelAcceleration>0</wheelAcceleration>
    <wheelTorque>5</wheelTorque>
    <publishTf>1</publishTf>

    </plugin>
  </gazebo>

<gazebo reference="kinect_Link">   
 <sensor type="depth" name="kinect">     
   <always_on>true</always_on>    
    <update_rate>20.0</update_rate>    
    <camera>          
  <horizontal_fov>${60.0*M_PI/180.0}</horizontal_fov>     
       <image>               
 <format>R8G8B8</format>             
   <width>640</width>              
  <height>480</height>          
  </image>        
    <clip>               
 <near>0.05</near>             
   <far>8.0</far>          
  </clip>      
  </camera>      
  <plugin name="kinect_controller" filename="libgazebo_ros_openni_kinect.so">         
   <cameraName>kinect1</cameraName>       
     <alwaysOn>true</alwaysOn>         
   <updateRate>10</updateRate>        
    <imageTopicName>rgb/image_raw</imageTopicName>   
    <depthImageTopicName>depth/image_raw</depthImageTopicName>    
    <pointCloudTopicName>depth/points</pointCloudTopicName>         
   <cameraInfoTopicName>rgb/camera_info</cameraInfoTopicName>       
   <depthImageCameraInfoTopicName>depth/camera_info</depthImageCameraInfoTopicName>         
   <frameName>kinect_Link</frameName>     
   <baseline>0.1</baseline>          
  <distortion_k1>0.0</distortion_k1>
      <distortion_k2>0.0</distortion_k2>   
      <distortion_k3>0.0</distortion_k3>      
      <distortion_t1>0.0</distortion_t1>     
      <distortion_t2>0.0</distortion_t2>     
      <pointCloudCutoff>0.4</pointCloudCutoff>    
    </plugin>  
  </sensor> 
</gazebo>


  <!-- hokuyo -->
  <gazebo reference="laser_Link">
    <sensor type="gpu_ray" name="head_hokuyo_sensor">
      <pose>0 0 0 0 0 0</pose>
      <visualize>false</visualize>
      <update_rate>40</update_rate>
      <ray>
        <scan>
          <horizontal>
            <samples>720</samples>
            <resolution>1</resolution>
            <min_angle>-1.570796</min_angle>
            <max_angle>1.570796</max_angle>
          </horizontal>
        </scan>
        <range>
          <min>0.10</min>
          <max>30.0</max>
          <resolution>0.01</resolution>
        </range>
        <noise>
          <type>gaussian</type>
          <!-- Noise parameters based on published spec for Hokuyo laser
               achieving "+-30mm" accuracy at range < 10m.  A mean of 0.0m and
               stddev of 0.01m will put 99.7% of samples within 0.03m of the true
               reading. -->
          <mean>0.0</mean>
          <stddev>0.01</stddev>
        </noise>
      </ray>
      <plugin name="gazebo_ros_head_hokuyo_controller" filename="libgazebo_ros_gpu_laser.so">
        <topicName>/scan</topicName>
        <frameName>laser_Link</frameName>
      </plugin>
    </sensor>
  </gazebo>
</robot>
